<sdf version='1.6'>
  <model name='spot_micro'>
    <link name='base_link'>
      <visual name='base_visual'>
        <geometry>
          <mesh>
            <uri>../meshes/mainbody.stl</uri>
            <scale>0.001 0.001 0.001</scale>
          </mesh>
        </geometry>
        <pose>-0.045 -0.060 -0.015 0 0 0</pose>
      </visual>
      <collision name='base_collision'>
        <geometry>
          <box>
            <size>0.14 0.11 0.07</size>
          </box>
        </geometry>
        <pose>0 0 1 0 0 0</pose>
      </collision>
      <inertial>
        <mass>2.80</mass>
        <inertia>
          <ixx>100</ixx>
          <ixy>0</ixy>
          <ixz>0</ixz>
          <iyy>100</iyy>
          <iyz>0</iyz>
          <izz>100</izz>
        </inertia>
      </inertial>
    </link>

    <link name='front_left_shoulder_link'>
      <visual name='front_left_shoulder_visual'>
        <geometry>
          <mesh>
            <uri>../meshes/lshoulder.stl</uri>
            <scale>0.001 0.001 0.001</scale>
          </mesh>
        </geometry>
        <pose>-0.135 -0.02 -0.01 0 0 0</pose>
      </visual>
      <collision name='front_left_shoulder_collision'>
        <geometry>
          <box>
            <size>0.044 0.038 0.07</size>
          </box>
        </geometry>
        <pose>0 0 0 0 0 0</pose>
      </collision>
      <inertial>
        <mass>0.10</mass>
        <inertia>
          <ixx>100</ixx>
          <ixy>0</ixy>
          <ixz>0</ixz>
          <iyy>100</iyy>
          <iyz>0</iyz>
          <izz>100</izz>
        </inertia>
      </inertial>
    </link>

    <link name='front_left_leg_link_cover'>
      <visual name='front_left_leg_cover_visual'>
        <geometry>
          <mesh>
            <uri>../meshes/larm_cover.stl</uri>
            <scale>0.001 0.001 0.001</scale>
          </mesh>
        </geometry>
        <pose>-0.125 0.04 -0.02 0 0 0</pose>
      </visual>
    </link>

    <link name='front_left_leg_link'>
      <visual name='front_left_leg_visual'>
        <geometry>
          <mesh>
            <uri>../meshes/larm.stl</uri>
            <scale>0.001 0.001 0.001</scale>
          </mesh>
        </geometry>
        <pose>-0.125 0.04 -0.02 0 0 0</pose>
      </visual>
      <collision name='front_left_leg_collision'>
        <geometry>
          <box>
            <size>0.028 0.036 0.12</size>
          </box>
        </geometry>
        <pose>0 0 -0.050 0 0 0</pose>
      </collision>
      <inertial>
        <mass>0.15</mass>
        <inertia>
          <ixx>1000</ixx>
          <ixy>0</ixy>
          <ixz>0</ixz>
          <iyy>1000</iyy>
          <iyz>0</iyz>
          <izz>1000</izz>
        </inertia>
      </inertial>
    </link>

    <link name='front_left_foot_link'>
      <visual name='front_left_foot_visual'>
        <geometry>
          <mesh>
            <uri>../meshes/lfoot.stl</uri>
            <scale>0.001 0.001 0.001</scale>
          </mesh>
        </geometry>
        <pose>-0.120 0.04 0.1 0 0 0</pose>
      </visual>
      <collision name='front_left_foot_collision'>
        <geometry>
          <box>
            <size>0.026 0.020 0.115</size>
          </box>
        </geometry>
        <pose>0 0 -0.050 0 0 0</pose>
      </collision>
      <inertial>
        <mass>0.1</mass>
        <inertia>
          <ixx>1000</ixx>
          <ixy>0</ixy>
          <ixz>0</ixz>
          <iyy>1000</iyy>
          <iyz>0</iyz>
          <izz>1000</izz>
        </inertia>
      </inertial>
    </link>

    <link name='front_left_toe_link'>
      <visual name='front_left_toe_visual'>
        <geometry>
          <mesh>
            <uri>../meshes/foot.stl</uri>
            <scale>0.001 0.001 0.001</scale>
          </mesh>
        </geometry>
        <pose>0 -0.01 0 0 -0.4001 0</pose>
      </visual>
      <collision name='front_left_toe_collision'>
        <geometry>
          <sphere>
            <radius>0.02</radius>
          </sphere>
        </geometry>
        <pose>0 0 0 0 0 0</pose>
      </collision>
      <inertial>
        <mass>0.05</mass>
        <inertia>
          <ixx>1000</ixx>
          <ixy>0</ixy>
          <ixz>0</ixz>
          <iyy>1000</iyy>
          <iyz>0</iyz>
          <izz>1000</izz>
        </inertia>
      </inertial>
    </link>

    <joint name='front_left_shoulder' type='revolute'>
      <parent>base_link</parent>
      <child>front_left_shoulder_link</child>
      <axis>
        <xyz>1 0 0</xyz>
        <limit>
            <effort>1000.0</effort>
            <lower>-0.548</lower>
            <upper>0.548</upper>
            <velocity>0.7</velocity>
        </limit>
        <dynamics>
            <damping>0.0</damping>
            <friction>0.5</friction>
        </dynamics>
      </axis>
      <pose relative_to='base_link'>-0.093 -0.036 0 0 0 0</pose>
    </joint>

    <joint name='front_left_leg' type='revolute'>
      <parent>front_left_shoulder_link</parent>
      <child>front_left_leg_link</child>
      <axis>
        <xyz>0 1 0</xyz>
        <limit>
            <effort>1000.0</effort>
            <lower>-2.666</lower>
            <upper>1.548</upper>
            <velocity>0.5</velocity>
        </limit>
        <dynamics>
            <damping>0.0</damping>
            <friction>0.0</friction>
        </dynamics>
      </axis>
      <pose relative_to='front_left_shoulder_link'>0 -0.052 0 0 0 0</pose>

    </joint>

    <joint name='front_left_leg_cover_joint' type='fixed'>
      <parent>front_left_leg_link</parent>
      <child>front_left_leg_link_cover</child>
      <pose relative_to='front_left_leg_link'>0 0 0 0 0 0</pose>
    </joint>

    <joint name='front_left_foot' type='revolute'>
      <parent>front_left_leg_link</parent>
      <child>front_left_foot_link</child>
      <axis>
        <xyz>0 1 0</xyz>
        <limit>
            <effort>1000.0</effort>
            <lower>-0.1</lower>
            <upper>2.59</upper>
            <velocity>0.5</velocity>
        </limit>
        <dynamics>
            <damping>0.0</damping>
            <friction>0.5</friction>
        </dynamics>
      </axis>
      <pose relative_to='front_left_leg_link'>-0.01 0 -0.12 0 0 0</pose>
    </joint>

    <joint name='front_left_toe' type='fixed'>
      <parent>front_left_foot_link</parent>
      <child>front_left_toe_link</child>
      <pose relative_to='front_left_foot_link'>0 0 -0.115 0 0 0</pose>
    </joint>
  </model>
</sdf>
